
#### Integrations

##### Exabeam

- Fixed an issue where this integration caused a "ValueError" exception.
- Updated the Docker image to: *demisto/python3:3.10.14.91134*.
